<?xml version='1.0' encoding='utf-8'?>
<sdf version="1.11" intrinsic="https://intrinsic.ai/">
  <model name="egk_25">
    <link name="SCHUNK_1491752_EGK_25_PN_M_B_000ohne0">
      <inertial>
        <pose>0.0 0.041979 0.0 0 -0 0</pose>
        <mass>0.15</mass>
      </inertial>
      <collision name="SCHUNK_1491752_EGK_25_PN_M_B_000ohne0_fixed_joint_lump__SCHUNK__Gehaeuse_EGK_25_PN_EI_0_0_collision">
        <pose>0.0 0.0 0.0 0 -0 0</pose>
        <geometry>
          <mesh>
            <scale>1 1 1</scale>
            <uri>SCHUNK__Gehaeuse_EGK_25_PN_EI_0_1.obj</uri>
          </mesh>
        </geometry>
      </collision>
      <collision name="SCHUNK_1491752_EGK_25_PN_M_B_000ohne0_fixed_joint_lump__SCHUNK__Gehaeuse_EGK_25_PN_EI_0_0_collision_1">
        <pose>0.0 0.0 0.0 0 -0 0</pose>
        <geometry>
          <mesh>
            <scale>1 1 1</scale>
            <uri>SCHUNK__Gehaeuse_EGK_25_PN_EI_0_2.obj</uri>
          </mesh>
        </geometry>
      </collision>
      <collision name="SCHUNK_1491752_EGK_25_PN_M_B_000ohne0_fixed_joint_lump__SCHUNK__Gehaeuse_EGK_25_PN_EI_0_0_collision_2">
        <pose>0.0 0.0 0.0 0 -0 0</pose>
        <geometry>
          <mesh>
            <scale>1 1 1</scale>
            <uri>SCHUNK__Gehaeuse_EGK_25_PN_EI_0_3.obj</uri>
          </mesh>
        </geometry>
      </collision>
      <collision name="SCHUNK_1491752_EGK_25_PN_M_B_000ohne0_fixed_joint_lump__SCHUNK__Gehaeuse_EGK_25_PN_EI_0_0_collision_3">
        <pose>0.0 0.0 0.0 0 -0 0</pose>
        <geometry>
          <mesh>
            <scale>1 1 1</scale>
            <uri>SCHUNK__Gehaeuse_EGK_25_PN_EI_0_4.obj</uri>
          </mesh>
        </geometry>
      </collision>
      <collision name="SCHUNK_1491752_EGK_25_PN_M_B_000ohne0_fixed_joint_lump__SCHUNK_9905503_Typenschild_11x43x0_3_1_collision_4">
        <pose>0.0297532 0.06296840000000001 0.0 -3.10669 -1.5708 0</pose>
        <geometry>
          <mesh>
            <scale>1 1 1</scale>
            <uri>SCHUNK_9905503_Typenschild_11x43x0_3_5.obj</uri>
          </mesh>
        </geometry>
      </collision>
      <collision name="SCHUNK_1491752_EGK_25_PN_M_B_000ohne0_fixed_joint_lump__SCHUNK_9905503_Typenschild_11x43x0_3_1_collision_5">
        <pose>0.0297532 0.06296840000000001 0.0 -3.10669 -1.5708 0</pose>
        <geometry>
          <mesh>
            <scale>1 1 1</scale>
            <uri>SCHUNK_9905503_Typenschild_11x43x0_3_6.obj</uri>
          </mesh>
        </geometry>
      </collision>
      <collision name="SCHUNK_1491752_EGK_25_PN_M_B_000ohne0_fixed_joint_lump__SCHUNK_9905503_Typenschild_11x43x0_3_1_collision_6">
        <pose>0.0297532 0.06296840000000001 0.0 -3.10669 -1.5708 0</pose>
        <geometry>
          <mesh>
            <scale>1 1 1</scale>
            <uri>SCHUNK_9905503_Typenschild_11x43x0_3_7.obj</uri>
          </mesh>
        </geometry>
      </collision>
      <collision name="SCHUNK_1491752_EGK_25_PN_M_B_000ohne0_fixed_joint_lump__SCHUNK_9905503_Typenschild_11x43x0_3_1_collision_7">
        <pose>0.0297532 0.06296840000000001 0.0 -3.10669 -1.5708 0</pose>
        <geometry>
          <mesh>
            <scale>1 1 1</scale>
            <uri>SCHUNK_9905503_Typenschild_11x43x0_3_8.obj</uri>
          </mesh>
        </geometry>
      </collision>
      <collision name="SCHUNK_1491752_EGK_25_PN_M_B_000ohne0_fixed_joint_lump__SCHUNK_9905503_Typenschild_11x43x0_3_2_collision_8">
        <pose>-0.0297532 0.06296840000000001 -0.0 -3.10669 1.5708 0</pose>
        <geometry>
          <mesh>
            <scale>1 1 1</scale>
            <uri>SCHUNK_9905503_Typenschild_11x43x0_3_9.obj</uri>
          </mesh>
        </geometry>
      </collision>
      <collision name="SCHUNK_1491752_EGK_25_PN_M_B_000ohne0_fixed_joint_lump__SCHUNK_9905503_Typenschild_11x43x0_3_2_collision_9">
        <pose>-0.0297532 0.06296840000000001 -0.0 -3.10669 1.5708 0</pose>
        <geometry>
          <mesh>
            <scale>1 1 1</scale>
            <uri>SCHUNK_9905503_Typenschild_11x43x0_3_10.obj</uri>
          </mesh>
        </geometry>
      </collision>
      <collision name="SCHUNK_1491752_EGK_25_PN_M_B_000ohne0_fixed_joint_lump__SCHUNK_9905503_Typenschild_11x43x0_3_2_collision_10">
        <pose>-0.0297532 0.06296840000000001 -0.0 -3.10669 1.5708 0</pose>
        <geometry>
          <mesh>
            <scale>1 1 1</scale>
            <uri>SCHUNK_9905503_Typenschild_11x43x0_3_11.obj</uri>
          </mesh>
        </geometry>
      </collision>
      <collision name="SCHUNK_1491752_EGK_25_PN_M_B_000ohne0_fixed_joint_lump__SCHUNK_9905503_Typenschild_11x43x0_3_2_collision_11">
        <pose>-0.0297532 0.06296840000000001 -0.0 -3.10669 1.5708 0</pose>
        <geometry>
          <mesh>
            <scale>1 1 1</scale>
            <uri>SCHUNK_9905503_Typenschild_11x43x0_3_12.obj</uri>
          </mesh>
        </geometry>
      </collision>
      <visual name="SCHUNK_1491752_EGK_25_PN_M_B_000ohne0_fixed_joint_lump__SCHUNK__Gehaeuse_EGK_25_PN_EI_0_0_visual">
        <pose>0.0 0.0 0.0 0 -0 0</pose>
        <geometry>
          <mesh>
            <scale>1 1 1</scale>
            <uri>SCHUNK__Gehaeuse_EGK_25_PN_EI_0_1.obj</uri>
          </mesh>
        </geometry>
      </visual>
      <visual name="SCHUNK_1491752_EGK_25_PN_M_B_000ohne0_fixed_joint_lump__SCHUNK__Gehaeuse_EGK_25_PN_EI_0_0_visual_1">
        <pose>0.0 0.0 0.0 0 -0 0</pose>
        <geometry>
          <mesh>
            <scale>1 1 1</scale>
            <uri>SCHUNK__Gehaeuse_EGK_25_PN_EI_0_2.obj</uri>
          </mesh>
        </geometry>
      </visual>
      <visual name="SCHUNK_1491752_EGK_25_PN_M_B_000ohne0_fixed_joint_lump__SCHUNK__Gehaeuse_EGK_25_PN_EI_0_0_visual_2">
        <pose>0.0 0.0 0.0 0 -0 0</pose>
        <geometry>
          <mesh>
            <scale>1 1 1</scale>
            <uri>SCHUNK__Gehaeuse_EGK_25_PN_EI_0_3.obj</uri>
          </mesh>
        </geometry>
      </visual>
      <visual name="SCHUNK_1491752_EGK_25_PN_M_B_000ohne0_fixed_joint_lump__SCHUNK__Gehaeuse_EGK_25_PN_EI_0_0_visual_3">
        <pose>0.0 0.0 0.0 0 -0 0</pose>
        <geometry>
          <mesh>
            <scale>1 1 1</scale>
            <uri>SCHUNK__Gehaeuse_EGK_25_PN_EI_0_4.obj</uri>
          </mesh>
        </geometry>
      </visual>
      <visual name="SCHUNK_1491752_EGK_25_PN_M_B_000ohne0_fixed_joint_lump__SCHUNK_9905503_Typenschild_11x43x0_3_1_visual_4">
        <pose>0.0297532 0.06296840000000001 0.0 -3.10669 -1.5708 0</pose>
        <geometry>
          <mesh>
            <scale>1 1 1</scale>
            <uri>SCHUNK_9905503_Typenschild_11x43x0_3_5.obj</uri>
          </mesh>
        </geometry>
      </visual>
      <visual name="SCHUNK_1491752_EGK_25_PN_M_B_000ohne0_fixed_joint_lump__SCHUNK_9905503_Typenschild_11x43x0_3_1_visual_5">
        <pose>0.0297532 0.06296840000000001 0.0 -3.10669 -1.5708 0</pose>
        <geometry>
          <mesh>
            <scale>1 1 1</scale>
            <uri>SCHUNK_9905503_Typenschild_11x43x0_3_6.obj</uri>
          </mesh>
        </geometry>
      </visual>
      <visual name="SCHUNK_1491752_EGK_25_PN_M_B_000ohne0_fixed_joint_lump__SCHUNK_9905503_Typenschild_11x43x0_3_1_visual_6">
        <pose>0.0297532 0.06296840000000001 0.0 -3.10669 -1.5708 0</pose>
        <geometry>
          <mesh>
            <scale>1 1 1</scale>
            <uri>SCHUNK_9905503_Typenschild_11x43x0_3_7.obj</uri>
          </mesh>
        </geometry>
      </visual>
      <visual name="SCHUNK_1491752_EGK_25_PN_M_B_000ohne0_fixed_joint_lump__SCHUNK_9905503_Typenschild_11x43x0_3_1_visual_7">
        <pose>0.0297532 0.06296840000000001 0.0 -3.10669 -1.5708 0</pose>
        <geometry>
          <mesh>
            <scale>1 1 1</scale>
            <uri>SCHUNK_9905503_Typenschild_11x43x0_3_8.obj</uri>
          </mesh>
        </geometry>
      </visual>
      <visual name="SCHUNK_1491752_EGK_25_PN_M_B_000ohne0_fixed_joint_lump__SCHUNK_9905503_Typenschild_11x43x0_3_2_visual_8">
        <pose>-0.0297532 0.06296840000000001 -0.0 -3.10669 1.5708 0</pose>
        <geometry>
          <mesh>
            <scale>1 1 1</scale>
            <uri>SCHUNK_9905503_Typenschild_11x43x0_3_9.obj</uri>
          </mesh>
        </geometry>
      </visual>
      <visual name="SCHUNK_1491752_EGK_25_PN_M_B_000ohne0_fixed_joint_lump__SCHUNK_9905503_Typenschild_11x43x0_3_2_visual_9">
        <pose>-0.0297532 0.06296840000000001 -0.0 -3.10669 1.5708 0</pose>
        <geometry>
          <mesh>
            <scale>1 1 1</scale>
            <uri>SCHUNK_9905503_Typenschild_11x43x0_3_10.obj</uri>
          </mesh>
        </geometry>
      </visual>
      <visual name="SCHUNK_1491752_EGK_25_PN_M_B_000ohne0_fixed_joint_lump__SCHUNK_9905503_Typenschild_11x43x0_3_2_visual_10">
        <pose>-0.0297532 0.06296840000000001 -0.0 -3.10669 1.5708 0</pose>
        <geometry>
          <mesh>
            <scale>1 1 1</scale>
            <uri>SCHUNK_9905503_Typenschild_11x43x0_3_11.obj</uri>
          </mesh>
        </geometry>
      </visual>
      <visual name="SCHUNK_1491752_EGK_25_PN_M_B_000ohne0_fixed_joint_lump__SCHUNK_9905503_Typenschild_11x43x0_3_2_visual_11">
        <pose>-0.0297532 0.06296840000000001 -0.0 -3.10669 1.5708 0</pose>
        <geometry>
          <mesh>
            <scale>1 1 1</scale>
            <uri>SCHUNK_9905503_Typenschild_11x43x0_3_12.obj</uri>
          </mesh>
        </geometry>
      </visual>
    </link>
    <joint name="Finger_Drive" type="prismatic">
      <pose relative_to="SCHUNK_1491752_EGK_25_PN_M_B_000ohne0">0.0 3e-09 0.0 0 0 0</pose>
      <parent>SCHUNK_1491752_EGK_25_PN_M_B_000ohne0</parent>
      <child>SCHUNK_1500102Grundbacke_EGK_25_3</child>
      <axis>
        <xyz>0 0 1</xyz>
        <limit>
          <lower>0</lower>
          <upper>0.0265</upper>
          <effort>1e+07</effort>
          <velocity>0</velocity>
        </limit>
        <dynamics>
          <spring_reference>0</spring_reference>
          <spring_stiffness>0</spring_stiffness>
        </dynamics>
      </axis>
    </joint>
    <link name="SCHUNK_1500102Grundbacke_EGK_25_3">
      <pose relative_to="Finger_Drive">0.0 0.0 0.0 0 -0 0</pose>
      <inertial>
        <pose>0.0 0.0 0.0 0 -0 0</pose>
        <mass>0.05</mass>
      </inertial>
      <collision name="SCHUNK_1500102Grundbacke_EGK_25_3_collision">
        <pose>-0.01314 0.0702 -0.01325 0 1.5708 0</pose>
        <geometry>
          <mesh>
            <scale>1 1 1</scale>
            <uri>SCHUNK_1500102Grundbacke_EGK_25_13.obj</uri>
          </mesh>
        </geometry>
      </collision>
      <visual name="SCHUNK_1500102Grundbacke_EGK_25_3_visual">
        <pose>-0.01314 0.0702 -0.01325 0 1.5708 0</pose>
        <geometry>
          <mesh>
            <scale>1 1 1</scale>
            <uri>SCHUNK_1500102Grundbacke_EGK_25_13.obj</uri>
          </mesh>
        </geometry>
      </visual>
    </link>
    <joint name="PrismaticJoint0" type="prismatic">
      <pose relative_to="SCHUNK_1491752_EGK_25_PN_M_B_000ohne0">-0.0 3e-09 0.0 0 -0 0</pose>
      <parent>SCHUNK_1491752_EGK_25_PN_M_B_000ohne0</parent>
      <child>SCHUNK_1500102Grundbacke_EGK_25_4</child>
      <axis>
        <xyz>0 0 1</xyz>
        <limit>
          <lower>-0.0265</lower>
          <upper>0</upper>
          <effort>0</effort>
          <velocity>0</velocity>
        </limit>
        <dynamics>
          <spring_reference>0</spring_reference>
          <spring_stiffness>0</spring_stiffness>
        </dynamics>
      </axis>
    </joint>
    <link name="SCHUNK_1500102Grundbacke_EGK_25_4">
      <pose relative_to="PrismaticJoint0">0.0 0.0 0.0 0 -0 0</pose>
      <inertial>
        <pose>0.0 0.0 0.0 0 -0 0</pose>
        <mass>0.05</mass>
      </inertial>
      <collision name="SCHUNK_1500102Grundbacke_EGK_25_4_collision">
        <pose>0.01314 0.0702 0.01325 0 -1.5708 0</pose>
        <geometry>
          <mesh>
            <scale>1 1 1</scale>
            <uri>SCHUNK_1500102Grundbacke_EGK_25_14.obj</uri>
          </mesh>
        </geometry>
      </collision>
      <visual name="SCHUNK_1500102Grundbacke_EGK_25_4_visual">
        <pose>0.01314 0.0702 0.01325 0 -1.5708 0</pose>
        <geometry>
          <mesh>
            <scale>1 1 1</scale>
            <uri>SCHUNK_1500102Grundbacke_EGK_25_14.obj</uri>
          </mesh>
        </geometry>
      </visual>
    </link>
  </model>
  </sdf>
